Workbook

Sheet Accuracy Calculation sheet 
A2: Sample Details | G2: Standard Details
A3: Date | G3: Name | H3: Amphotericin B USP RS
A4: Product Name | B4: Amphotericin B API | G4: Batch No. | H4: R087G0
A5: Batch No. | B5: HAN1711203U | G5: Potency | H5: 994
A6: Condition | B6: 2 to 8°C (Protect from light) | G6: Valid up to | H6: NA
A9: Standard Stcok Solution Preapration
A10: Name | B10: Weight in mg | C10: Dilution (*mL) | D10: Sample Taken (*mL) | E10: Dilution(*mL) | F10: Concentration(µg/mL) | G10: Volume taken (mL) | H10: Dilution (**mL) | I10: Concentration (µg/mL) | J10: Std. Name | K10: Log Concentration
A11: Amphotericin B USPRS | B11: 10.05 | C11: 10 | D11: 0.643 | E11: 50 | F11: =B11/C11*D11/E11*H5 -> 12.846754 | G11: 1 | H11: 20 | I11: =(B11/C11*D11/E11*G11/H11*H5) -> 0.64233771 | J11: S1 | K11: =ROUND(LN(I11),4) -> -0.4426
D12: 0.803 | E12: 50 | F12: =B11/C11*D12/E12*H5 -> 16.043458 | G12: 1 | H12: 20 | I12: =(B11/C11*D12/E12*G12/H12*H5) -> 0.80217291 | J12: S2 | K12: =ROUND(LN(I12),4) -> -0.2204
D13: 1 | E13: 50 | F13: =B11/C11*D13/E13*H5 -> 19.9794 | G13: 1 | H13: 20 | I13: =(B11/C11*D13/E13*G13/H13*H5) -> 0.99897 | J13: S3 | K13: =ROUND(LN(I13),4) -> -0.001
D14: 1.255 | E14: 50 | F14: =B11/C11*D14/E14*H5 -> 25.074147 | G14: 1 | H14: 20 | I14: =(B11/C11*D14/E14*G14/H14*H5) -> 1.2537073 | J14: S4 | K14: =ROUND(LN(I14),4) -> 0.2261
D15: 1.566 | E15: 50 | F15: =B11/C11*D15/E15*H5 -> 31.28774 | G15: 1 | H15: 20 | I15: =(B11/C11*D15/E15*G15/H15*H5) -> 1.564387 | J15: S5 | K15: =ROUND(LN(I15),4) -> 0.4475
A16: Where, * =Dimethyl sulphoxide, ** = Buffer solution pH 10.5
A18: Sample Preparation
A19: Name | B19: Weight in mg | C19: Dilution (*mL) | D19: Dilution (*mL) | E19: Dilution (*mL) | F19: Concentration(µg/mL) | G19: Dilution (*mL) | H19: Dilution (**mL) | I19: Concentration(µg/mL)
A20: Amphotericin B API (Set-1) | B20: 10.043 | C20: 10 | D20: 1 | E20: 50 | F20: =B20/C20*D20/E20*1000 -> 20.086 | G20: 1 | H20: 20 | I20: =F20*G20/H20 -> 1.0043
A21: Amphotericin B API (Set-2) | B21: 10.046 | C21: 10 | D21: 1 | E21: 50 | F21: =B21/C21*D21/E21*1000 -> 20.092 | G21: 1 | H21: 20 | I21: =F21*G21/H21 -> 1.0046
A22: Amphotericin B API (Set-3) | B22: 10.049 | C22: 10 | D22: 1 | E22: 50 | F22: =B22/C22*D22/E22*1000 -> 20.098 | G22: 1 | H22: 20 | I22: =F22*G22/H22 -> 1.0049
A40: Standard Name | B40: Log Concentration | C40: Plates | D40: Reference zone (Reading in mm) | I40: Sample Zone (Reading in mm)
D41: Zone 1 | E41: Zone 3 | F41: Zone 5 | G41: Average | H41: % RSD | I41: Zone 2 | J41: Zone 4 | K41: Zone 6 | L41: Average | M41: % RSD | N41: Corrected Mean
A42: S1 | B42: =K11 -> -0.4426 | C42: 1 | D42: 14.11 | E42: 14.16 | F42: 14.44 | G42: =AVERAGE(D42:F44) -> 14.39 | H42: =STDEV(D42:F44)*100/G42 -> 1.8244316 | I42: 13.61 | J42: 13.47 | K42: 13.74 | L42: =AVERAGE(I42:K44) -> 13.477778 | M42: =STDEV(I42:K44)*100/L42 -> 2.2217948 | N42: =L42-(G42-G54) -> 13.530556
C43: 2 | D43: 14 | E43: 14.34 | F43: 14.81 | I43: 13.48 | J43: 13.6 | K43: 13.9
C44: 3 | D44: 14.52 | E44: 14.5 | F44: 14.63 | I44: 13 | J44: 13.48 | K44: 13.02
A45: S2 | B45: =K12 -> -0.2204 | C45: 1 | D45: 14.69 | E45: 14.1 | F45: 14.48 | G45: =AVERAGE(D45:F47) -> 14.606667 | H45: =STDEV(D45:F47)*100/G45 -> 1.9723679 | I45: 14.14 | J45: 14.72 | K45: 14.6 | L45: =AVERAGE(I45:K47) -> 14.474444 | M45: =STDEV(I45:K47)*100/L45 -> 1.8350806 | N45: =L45-(G45-G54) -> 14.310556
C46: 2 | D46: 14.32 | E46: 14.45 | F46: 14.78 | I46: 14.5 | J46: 14.34 | K46: 14.91
C47: 3 | D47: 15 | E47: 14.79 | F47: 14.85 | I47: 14.64 | J47: 14.19 | K47: 14.23
A48: S4 | B48: =K14 -> 0.2261 | C48: 1 | D48: 14.78 | E48: 14.6 | F48: 14.64 | G48: =AVERAGE(D48:F50) -> 14.45 | H48: =STDEV(D48:F50)*100/G48 -> 1.3203311 | I48: 15.04 | J48: 15.9 | K48: 15.53 | L48: =AVERAGE(I48:K50) -> 15.164444 | M48: =STDEV(I48:K50)*100/L48 -> 2.8753868 | N48: =L48-(G48-G54) -> 15.157222
C49: 2 | D49: 14.46 | E49: 14.22 | F49: 14.25 | I49: 14.48 | J49: 15 | K49: 15.45
C50: 3 | D50: 14.3 | E50: 14.44 | F50: 14.36 | I50: 14.67 | J50: 15.15 | K50: 15.26
A51: S5 | B51: =K15 -> 0.4475 | C51: 1 | D51: 14.2 | E51: 14.36 | F51: 14.41 | G51: =AVERAGE(D51:F53) -> 14.324444 | H51: =STDEV(D51:F53)*100/G51 -> 1.6769518 | I51: 15.8 | J51: 15.2 | K51: 16.48 | L51: =AVERAGE(I51:K53) -> 15.835556 | M51: =STDEV(I51:K53)*100/L51 -> 4.1186425 | N51: =L51-(G51-G54) -> 15.953889
C52: 2 | D52: 14 | E52: 14.48 | F52: 14.22 | I52: 15.26 | J52: 15.14 | K52: 16.94
C53: 3 | D53: 14.55 | E53: 14.7 | F53: 14 | I53: 15.34 | J53: 16 | K53: 16.36
A54: S3 (Refernce) | B54: =K13 -> -0.001 | C54: Average | G54: =AVERAGE(G42:G53) -> 14.442778 | N54: =G54 -> 14.442778
A55: Sample Reading
A56: Sample Batch No. | B56: Log Concentration | C56: Plates | D56: Reference zone (Reading in mm) | I56: Sample Zone (Reading in mm)
D57: Zone 1 | E57: Zone 3 | F57: Zone 5 | G57: Average | H57: % RSD | I57: Zone 2 | J57: Zone 4 | K57: Zone 6 | L57: Average | M57: % RSD | N57: Corrected Mean (U)
A58: Amphotericin B API (Set-1) | C58: 1 | D58: 14.05 | E58: 14.46 | F58: 15.08 | G58: =AVERAGE(D58:F60) -> 14.545556 | H58: =STDEV(D58:F60)*100/G58 -> 2.4723821 | I58: 14.27 | J58: 15.79 | K58: 15.3 | L58: =AVERAGE(I58:K60) -> 15.014444 | M58: =STDEV(I58:K60)*100/L58 -> 3.2521394 | N58: =L58-(G58-G54) -> 14.911667
B59: NA | C59: 2 | D59: 15 | E59: 14.78 | F59: 14.47 | I59: 15.35 | J59: 15.18 | K59: 14.33
C60: 3 | D60: 14.15 | E60: 14.29 | F60: 14.63 | I60: 14.79 | J60: 15.12 | K60: 15
A61: Amphotericin B API (Set-2) | C61: 1 | D61: 14.4 | E61: 14.06 | F61: 15.48 | G61: =AVERAGE(D61:F63) -> 14.593333 | H61: =STDEV(D61:F63)*100/G61 -> 3.2208309 | I61: 14.22 | J61: 14.67 | K61: 15.49 | L61: =AVERAGE(I61:K63) -> 15.152222 | M61: =STDEV(I61:K63)*100/L61 -> 3.9450453 | N61: =L61-(G61-G54) -> 15.001667
...

Sheet Sheet2
D4: Log Concentration | E4: Corrected Zone Diameter
D5: -0.4462 | E5: ='Accuracy Calculation sheet '!N42 -> 13.530556
D6: -0.2224 | E6: ='Accuracy Calculation sheet '!N45 -> 14.310556
D7: ='Accuracy Calculation sheet '!B54 -> -0.001 | E7: ='Accuracy Calculation sheet '!N54 -> 14.442778
D8: 0.2236 | E8: ='Accuracy Calculation sheet '!N48 -> 15.157222
D9: 0.4447 | E9: ='Accuracy Calculation sheet '!N51 -> 15.953889
