Workbook

Sheet Final Bioassay sheet 
A2: Sample Details | I2: Standard Details
A3: Date | I3: Name | J3: Amphotercin B
A4: Product Name | B4: Amphotericin B Liposome for injection 50 mg / viaL | I4: Batch No. | J4: R087G0
A5: Batch No. | I5: Potency | J5: 994
A6: Label Claim | B6: Each vial contain 50 mg of Amphotericin B | I6: Valid up to | J6: NA
A7: Condition
A8: TRF No.
A10: Standard Stcok Solution Preapration
A11: Name | B11: Weight in mg | C11: Dilution (*mL) | D11: Sample Taken (*mL) | E11: Dilution (*mL) | F11: Concentration (µg/mL) | G11: Log Concentration | H11: Volume taken (mL) | I11: Dilution (**mL) | J11: Concentration (µg/mL) | K11: Std. Name | L11: Log Concentration
A12: Amphotericin B USPRS | B12: 10.05 | C12: 10 | D12: 0.64 | E12: 50 | F12: =B12/C12*D12/E12*J5 -> 12.786816 | G12: =LN(F12) -> 2.5484146 | H12: 1 | I12: 20 | J12: =(B12/C12*D12/E12*H12/I12*J5) -> 0.6393408 | K12: S1 | L12: =ROUND(LN(J12),4) -> -0.4473
D13: 0.8 | E13: 50 | F13: =B12/C12*D13/E13*J5 -> 15.98352 | G13: =LN(F13) -> 2.7715582 | H13: 1 | I13: 20 | J13: =(B12/C12*D13/E13*H13/I13*J5) -> 0.799176 | K13: S2 | L13: =ROUND(LN(J13),4) -> -0.2242
D14: 1 | E14: 50 | F14: =B12/C12*D14/E14*J5 -> 19.9794 | G14: =LN(F14) -> 2.9947017 | H14: 1 | I14: 20 | J14: =(B12/C12*D14/E14*H14/I14*J5) -> 0.99897 | K14: S3 | L14: =ROUND(LN(J14),4) -> -0.001
D15: 1.25 | E15: 50 | F15: =B12/C12*D15/E15*J5 -> 24.97425 | G15: =LN(F15) -> 3.2178453 | H15: 1 | I15: 20 | J15: =(B12/C12*D15/E15*H15/I15*J5) -> 1.2487125 | K15: S4 | L15: =ROUND(LN(J15),4) -> 0.2221
D16: 1.56 | E16: 50 | F16: =B12/C12*D16/E16*J5 -> 31.167864 | G16: =LN(F16) -> 3.4393876 | H16: 1 | I16: 20 | J16: =(B12/C12*D16/E16*H16/I16*J5) -> 1.5583932 | K16: S5 | L16: =ROUND(LN(J16),4) -> 0.4437
A17: Where, * = N,N, Dimethyl Formamide , ** = Buffer solution pH 10.5
A19: Sample Preparation
A20: Sample Details | B20: Amphotericin B Weight in mg | C20: Dilution (*mL) | D20: Dilution (*mL) | E20: Dilution (*mL) | F20: Concentration (µg/mL) | G20: Dilution (*mL) | H20: Dilution (**mL) | I20: Concentration(µg/mL) | J20: Average Weight (mg/vial)
B21: 1475 | C21: 50 | D21: 1 | E21: 50 | F21: =B21/C21*D21/E21*1000 -> 590 | G21: 1 | H21: 20 | I21: =F21*G21/H21 -> 29.5 | J21: =B21 -> 1475
B22: 1490 | C22: 50 | D22: 1 | E22: 50 | F22: =B21/C21*D22/E22*1000 -> 590 | G22: 1 | H22: 20 | I22: =F22*G22/H22 -> 29.5 | J22: =B22 -> 1490
A35: Standard Name | B35: Log Concentration | C35: Plates | D35: Reference zone (Reading in mm) | I35: Sample Zone (Reading in mm)
D36: Zone 1 | E36: Zone 3 | F36: Zone 5 | G36: Average | H36: % RSD | I36: Zone 2 | J36: Zone 4 | K36: Zone 6 | L36: Average | M36: % RSD | N36: Corrected Mean
A37: S1 | B37: =L12 -> -0.4473 | C37: 1 | D37: 14.13 | E37: 14 | F37: 14.46 | G37: =AVERAGE(D37:F39) -> 14.468889 | H37: =STDEV(D37:F39)*100/G37 -> 2.1202412 | I37: 13.21 | J37: 13.2 | K37: 13 | L37: =AVERAGE(I37:K39) -> 13.37 | M37: =STDEV(I37:K39)*100/L37 -> 1.9218646 | N37: =L37-(G37-G49) -> 13.352778
C38: 2 | D38: 14.51 | E38: 14.75 | F38: 14.56 | I38: 13.15 | J38: 13.49 | K38: 13.4
C39: 3 | D39: 14.63 | E39: 14.96 | F39: 14.22 | I39: 13.46 | J39: 13.84 | K39: 13.58
A40: S2 | B40: =L13 -> -0.2242 | C40: 1 | D40: 14.84 | E40: 14.38 | F40: 14.33 | G40: =AVERAGE(D40:F42) -> 14.653333 | H40: =STDEV(D40:F42)*100/G40 -> 1.4500816 | I40: 14.5 | J40: 14.38 | K40: 14.4 | L40: =AVERAGE(I40:K42) -> 14.568889 | M40: =STDEV(I40:K42)*100/L40 -> 1.0177656 | N40: =L40-(G40-G49) -> 14.367222
C41: 2 | D41: 14.95 | E41: 14.79 | F41: 14.7 | I41: 14.69 | J41: 14.76 | K41: 14.65
C42: 3 | D42: 14.76 | E42: 14.64 | F42: 14.49 | I42: 14.76 | J42: 14.5 | K42: 14.48
A43: S4 | B43: =L15 -> 0.2221 | C43: 1 | D43: 14.12 | E43: 14.55 | F43: 14.8 | G43: =AVERAGE(D43:F45) -> 14.377778 | H43: =STDEV(D43:F45)*100/G43 -> 1.7010983 | I43: 15.15 | J43: 15.48 | K43: 15.1 | L43: =AVERAGE(I43:K45) -> 15.41 | M43: =STDEV(I43:K45)*100/L43 -> 1.8624948 | N43: =L43-(G43-G49) -> 15.483889
C44: 2 | D44: 14.31 | E44: 14.3 | F44: 14.14 | I44: 15.25 | J44: 15.94 | K44: 15.43
C45: 3 | D45: 14.1 | E45: 14.48 | F45: 14.6 | I45: 15.36 | J45: 15.78 | K45: 15.2
A46: S5 | B46: =L16 -> 0.4437 | C46: 1 | D46: 14 | E46: 14.6 | F46: 14.2 | G46: =AVERAGE(D46:F48) -> 14.306667 | H46: =STDEV(D46:F48)*100/G46 -> 1.4607571 | I46: 16.01 | J46: 16.07 | K46: 16.14 | L46: =AVERAGE(I46:K48) -> 16.145556 | M46: =STDEV(I46:K48)*100/L46 -> 0.78717377 | N46: =L46-(G46-G49) -> 16.290556
C47: 2 | D47: 14.5 | E47: 14.35 | F47: 14.16 | I47: 16.16 | J47: 16.38 | K47: 16.3
C48: 3 | D48: 14.31 | E48: 14.1 | F48: 14.54 | I48: 16.08 | J48: 16 | K48: 16.17
A49: S3 (Refernce) | B49: =L14 -> -0.001 | C49: Average | G49: =AVERAGE(G37:G48) -> 14.451667 | H49: NA | N49: =G49 -> 14.451667
A50: Sample Reading
A51: Sample Batch No. | B51: Log Concentration | C51: Plates | D51: Reference zone (Reading in mm) | I51: Sample Zone (Reading in mm)
D52: Zone 1 | E52: Zone 3 | F52: Zone 5 | G52: Average | H52: % RSD | I52: Zone 2 | J52: Zone 4 | K52: Zone 6 | L52: Average | M52: % RSD | N52: Corrected Mean (U)
B53: NA | C53: 1 | D53: 14.5 | E53: 14.36 | F53: 14.53 | G53: =AVERAGE(D53:F55) -> 14.468889 | H53: =STDEV(D53:F55)*100/G53 -> 1.5467619 | I53: 15.27 | J53: 14.8 | K53: 15.29 | L53: =AVERAGE(I53:K55) -> 15.057778 | M53: =STDEV(I53:K55)*100/L53 -> 1.3109956 | N53: =L53-(G53-G49) -> 15.040556
C54: 2 | D54: 14.68 | E54: 14.46 | F54: 14.28 | I54: 14.79 | J54: 14.99 | K54: 15.14
C55: 3 | D55: 14.9 | E55: 14.14 | F55: 14.37 | I55: 15.21 | J55: 15.15 | K55: 14.88
...

Sheet Sheet2
D4: Log Concentration | E4: Corrected Zone Diameter
D5: ='Final Bioassay sheet '!L12 -> -0.4473 | E5: ='Final Bioassay sheet '!N37 -> 13.352778
D6: ='Final Bioassay sheet '!L13 -> -0.2242 | E6: ='Final Bioassay sheet '!N40 -> 14.367222
D7: ='Final Bioassay sheet '!L14 -> -0.001 | E7: ='Final Bioassay sheet '!G49 -> 14.451667
D8: ='Final Bioassay sheet '!L15 -> 0.2221 | E8: ='Final Bioassay sheet '!N43 -> 15.483889
D9: ='Final Bioassay sheet '!L16 -> 0.4437 | E9: ='Final Bioassay sheet '!N46 -> 16.290556
