Workbook

Sheet Lipid 
A1: Emcure
A3: R & D Ahmedabad
A4: Analytical Development
A5: Lipid Assay Calculation Sheet
A7: Generic Name | C7: Bupivacaine liposome injectable suspension (13.3 mg/ml)
A8: Product Name | C8: Bupivacaine liposome injectable suspension (13.3 mg/ml)
A9: Test | C9: Lipid Content
A10: Analysis as per | C10: AD/ATP/648/02
A11: Analysed By | C11: Mayur Kansara
A12: Instrument Id. | C12: AD/HPLC/006
A13: Date of Analysis | C13: 45621
A15: Standard Details
A17: Compound Name | B17: Weight in mg | C17: Vol | D17: Pip | E17: Vol | F17: Pip | G17: Vol | H17: Potency | I17: M.W of Base | J17: M.W. of Salt | K17: Conc. (ppm)
A18: Tricaprylin | B18: 99.1 | C18: 50 | D18: 6 | E18: 100 | F18: 1 | G18: 1 | H18: 100 | I18: 1 | J18: 1 | K18: =IFERROR((B18/C18*D18/E18*F18/G18*H18/100*I18/J18*1000), "") -> 118.92
A19: DPPG Na | B19: 46.79 | C19: 50 | D19: 6 | E19: 100 | F19: 1 | G19: 1 | H19: 99.3 | I19: 721.9602 | J19: 744.95 | K19: =IFERROR((B19/C19*D19/E19*F19/G19*H19/100*I19/J19*1000), "") -> 54.034318
A20: Cholesterol | B20: 28.51 | C20: 100 | D20: 1 | E20: 1 | F20: 1 | G20: 1 | H20: 100 | I20: 1 | J20: 1 | K20: =IFERROR((B20/C20*D20/E20*F20/G20*H20/100*I20/J20*1000), "") -> 285.1
A21: DEPC | B21: 49.32 | C21: 100 | D21: 1 | E21: 1 | F21: 1 | G21: 1 | H21: 99.2 | I21: 1 | J21: 1 | K21: =IFERROR((B21/C21*D21/E21*F21/G21*H21/100*I21/J21*1000), "") -> 489.2544
A23: Standard Details | B23: =A18 -> Tricaprylin | C23: DPPG | D23: =A20 -> Cholesterol | E23: =A21 -> DEPC | G23: BKT Std | H23: =A18 -> Tricaprylin | I23: =C23 -> DPPG | J23: =A20 -> Cholesterol | K23: =A21 -> DEPC
A24: Injection No. | B24: Area | C24: Area | D24: Area | E24: Area | G24: Injection No. | H24: Area | I24: Area | J24: Area | K24: Area
A25: 1 | B25: 8711513 | C25: 4437526 | D25: 32277247 | E25: 44369260 | G25: 1 | H25: 8713270 | I25: 4473297 | J25: 32509936 | K25: 43884434
A26: 2 | B26: 8674291 | C26: 4473096 | D26: 32439471 | E26: 44366857 | G26: 2 | H26: 8686255 | I26: 4509972 | J26: 32485699 | K26: 43979519
A27: 3 | B27: 8679908 | C27: 4461331 | D27: 32393636 | E27: 44211085 | G27: 3 | H27: 8719164 | I27: 4448498 | J27: 32455877 | K27: 43323151
A28: 4 | B28: 8671826 | C28: 4528571 | D28: 32357224 | E28: 43613144 | G28: 4 | H28: 8729929 | I28: 4472750 | J28: 32460029 | K28: 44269558
A29: 5 | B29: 8715229 | C29: 4403707 | D29: 32429381 | E29: 43626749 | G29: 5
A30: 6 | B30: 8695954 | C30: 4463992 | D30: 32523530 | E30: 43893218 | G30: 6
A31: Mean | B31: =IFERROR((AVERAGE(B25:B30)), "") -> 8691453.5 | C31: =IFERROR((AVERAGE(C25:C30)), "") -> 4461370.5 | D31: =IFERROR((AVERAGE(D25:D30)), "") -> 32403415 | E31: =IFERROR((AVERAGE(E25:E30)), "") -> 44013386 | G31: Mean | H31: =IFERROR((AVERAGE(H25:H30,B25:B30)), "") -> 8699733.9 | I31: =IFERROR((AVERAGE(I25:I30,C25:C30)), "") -> 4467274 | J31: =IFERROR((AVERAGE(J25:J30,D25:D30)), "") -> 32433203 | K31: =IFERROR((AVERAGE(K25:K30,E25:E30)), "") -> 43953698
A32: SD | B32: =IFERROR((STDEV(B25:B30)),"") -> 18978.942 | C32: =IFERROR((STDEV(C25:C30)),"") -> 41361.595 | D32: =IFERROR((STDEV(D25:D30)),"") -> 83125.788 | E32: =IFERROR((STDEV(E25:E30)),"") -> 350655.14 | G32: SD | H32: =IFERROR((STDEV(B25:B30,H25:H30)), "") -> 20727.252 | I32: =IFERROR((STDEV(C25:C30,I25:I30)), "") -> 34968.138 | J32: =IFERROR((STDEV(D25:D30,J25:J30)), "") -> 74349.789 | K32: =IFERROR((STDEV(E25:E30,K25:K30)), "") -> 355745.23
A33: % RSD | B33: =IFERROR((B32*100/B31),"") -> 0.21836327 | C33: =IFERROR((C32*100/C31),"") -> 0.92710514 | D33: =IFERROR((D32*100/D31),"") -> 0.25653404 | E33: =IFERROR((E32*100/E31),"") -> 0.79670112 | G33: % RSD | H33: =IFERROR((H32*100/H31), "") -> 0.23825157 | I33: =IFERROR((I32*100/I31), "") -> 0.78276233 | J33: =IFERROR((J32*100/J31), "") -> 0.22923974 | K33: =IFERROR((K32*100/K31), "") -> 0.80936359
A36: Sample Details
A38: Batch No. | B38: Storage Condition | C38: Packing Detail | D38: TRF No. | E38: AR No. | F38: Compound Name | G38: LC | H38: Avg Weight | I38: Sample Weight | J38: Vol | K38: Pip | L38: Vol | M38: Area | N38: % Assay | O38: % Mean
A39: EP20_117-299-B | B39: 2-8°C_3M | C39: Glass Vial | D39: TRF_068-24-089 | E39: AD/008/24/0701 | F39: =A18 -> Tricaprylin | G39: 2 | H39: 1.005 | I39: 1.5008 | J39: 25 | K39: 1 | L39: 1 | M39: 8729574 | N39: =IFERROR((M39/$B$31*B$18/$C$18*$D$18/$E$18*$F$18/$G$18*J39/I39*L39/K39*$H$18/G39*$I$18/$J$18*H39), "") -> 99.979001
F40: =C23 -> DPPG | G40: 0.9 | M40: 3826195 | N40: =IFERROR((M40/$C$31*$B$19/$C$19*$D$19/$E$19*$F$19/$G$19*J39/I39*L39/K39*$H$19/G40*$I$19/$J$19*H39), "") -> 86.200388
F41: =A20 -> Cholesterol | G41: 4.7 | M41: 32474189 | N41: =IFERROR((M41/$D$31*$B$20/$C$20*$D$20/$E$20*$F$20/$G$20*J39/I39*L39/K39*$H$20/G41*$I$20/$J$20*H39), "") -> 101.77243
F42: =A21 -> DEPC | G42: 8.2 | M42: 44235393 | N42: =IFERROR((M42/$E$31*$B$21/$C$21*$D$21/$E$21*$F$21/$G$21*J39/I39*L39/K39*$H$21/G42*$I$21/$J$21*H39), "") -> 100.38972
F43: Tricaprylin | G43: =G39 -> 2 | H43: =H39 -> 1.005 | J43: =J39 -> 25 | K43: =K39 -> 1 | L43: =L39 -> 1 | N43: =IFERROR((M43/$B$31*B$18/$C$18*$D$18/$E$18*$F$18/$G$18*J43/I43*L43/K43*$H$18/G43*$I$18/$J$18*H43), "") | O43: =IFERROR((AVERAGE(N39,N43)), "") -> 99.979001
F44: DPPG | G44: =G40 -> 0.9 | N44: =IFERROR((M44/$C$31*$B$19/$C$19*$D$19/$E$19*$F$19/$G$19*J43/I43*L43/K43*$H$19/G44*$I$19/$J$19*H43), "") | O44: =IFERROR((AVERAGE(N40,N44)), "") -> 86.200388
F45: Cholesterol | G45: =G41 -> 4.7 | N45: =IFERROR((M45/$D$31*$B$20/$C$20*$D$20/$E$20*$F$20/$G$20*J43/I43*L43/K43*$H$20/G45*$I$20/$J$20*H43), "") | O45: =IFERROR((AVERAGE(N41,N45)), "") -> 101.77243
F46: DEPC | G46: =G42 -> 8.2 | N46: =IFERROR((M46/$E$31*$B$21/$C$21*$D$21/$E$21*$F$21/$G$21*J43/I43*L43/K43*$H$21/G46*$I$21/$J$21*H43), "") | O46: =IFERROR((AVERAGE(N42,N46)), "") -> 100.38972
A48: EP20_117-299-C | B48: 2-8°C_3M | C48: Glass Vial | D48: TRF_068-24-091 | E48: AD/008/24/0702 | F48: Tricaprylin | G48: 2 | H48: 1.005 | I48: 1.5051 | J48: 25 | K48: 1 | L48: 1 | M48: 8576367 | N48: =IFERROR((M48/$B$31*B$18/$C$18*$D$18/$E$18*$F$18/$G$18*J48/I48*L48/K48*$H$18/G48*$I$18/$J$18*H48), "") -> 97.943713
F49: DPPG | G49: 0.9 | M49: 4183290 | N49: =IFERROR((M49/$C$31*$B$19/$C$19*$D$19/$E$19*$F$19/$G$19*J48/I48*L48/K48*$H$19/G49*$I$19/$J$19*H48), "") -> 93.97613
...

Sheet Drug to Lipid ratio Auto Calc
A1: Emcure
A3: R & D Ahmedabad
A4: Analytical Development
A5: Drug to Lipid Calculation Sheet
A7: Generic Name | C7: ='Lipid '!C7:K7 -> Bupivacaine liposome injectable suspension (13.3 mg/ml)
A8: Product Name | C8: ='Lipid '!C8:K8 -> Bupivacaine liposome injectable suspension (13.3 mg/ml)
A9: Test | C9: Drug to Lipid Ratio
A10: Analysis as per | C10: ='Lipid '!C10:K10 -> AD/ATP/648/02
A11: Analysed By | C11: ='Lipid '!C11:K11 -> Mayur Kansara
A12: Instrument Id. | C12: ='Lipid '!C12:K12 -> AD/HPLC/006
A13: Date of Analysis | C13: ='Lipid '!C13:K13 -> 45621
A15: Sample Details
A17: Batch No. | B17: Storage Condition | C17: Packing Detail | D17: TRF No. | E17: AR No. | F17: Compound Name | G17: L.C. (Lipid) | H17: % Mean (Lipid) | I17: mg/mL (Lipid) | J17: mg/mL (Sum of Lipid) | K17: % Assay of Bupivacaine | L17: L.C. of Bupivacaine | M17: mg/mL of Bupivacaine | N17: Drug/Lipid Ratio
A18: ='Lipid '!A39 -> EP20_117-299-B | B18: ='Lipid '!B39 -> 2-8°C_3M | C18: ='Lipid '!C39 -> Glass Vial | D18: ='Lipid '!D39 -> TRF_068-24-089 | E18: ='Lipid '!E39 -> AD/008/24/0701 | F18: Tricaprylin | G18: ='Lipid '!G39 -> 2 | H18: ='Lipid '!O43 -> 99.979001 | I18: =IFERROR((H18*G18/100), "") -> 1.99958 | J18: =IFERROR((SUM(I18:I21)), "") -> 15.790645 | K18: 99.9 | L18: 13.3 | M18: =IFERROR((K18*L18/100), "") -> 13.2867 | N18: =IFERROR((M18/J18), "") -> 0.84142859
F19: DPPG | G19: ='Lipid '!G40 -> 0.9 | H19: ='Lipid '!O44 -> 86.200388 | I19: =IFERROR((H19*G19/100), "") -> 0.77580349
F20: Cholesterol | G20: ='Lipid '!G41 -> 4.7 | H20: ='Lipid '!O45 -> 101.77243 | I20: =IFERROR((H20*G20/100), "") -> 4.7833042
F21: DEPC | G21: ='Lipid '!G42 -> 8.2 | H21: ='Lipid '!O46 -> 100.38972 | I21: =IFERROR((H21*G21/100), "") -> 8.2319572
A23: ='Lipid '!A48 -> EP20_117-299-C | B23: ='Lipid '!B48 -> 2-8°C_3M | C23: ='Lipid '!C48 -> Glass Vial | D23: ='Lipid '!D48 -> TRF_068-24-091 | E23: ='Lipid '!E48 -> AD/008/24/0702 | F23: Tricaprylin | G23: ='Lipid '!G48 -> 2 | H23: ='Lipid '!O52 -> 97.943713 | I23: =IFERROR((H23*G23/100), "") -> 1.9588743 | J23: =IFERROR((SUM(I23:I26)), "") -> 15.737112 | K23: 97.8 | L23: 13.3 | M23: =IFERROR((K23*L23/100), "") -> 13.0074 | N23: =IFERROR((M23/J23), "") -> 0.82654302
F24: DPPG | G24: ='Lipid '!G49 -> 0.9 | H24: ='Lipid '!O53 -> 93.97613 | I24: =IFERROR((H24*G24/100), "") -> 0.84578517
F25: Cholesterol | G25: ='Lipid '!G50 -> 4.7 | H25: ='Lipid '!O54 -> 101.39319 | I25: =IFERROR((H25*G25/100), "") -> 4.7654798
F26: DEPC | G26: ='Lipid '!G51 -> 8.2 | H26: ='Lipid '!O55 -> 99.597228 | I26: =IFERROR((H26*G26/100), "") -> 8.1669727
A28: ='Lipid '!A57 -> EP20_117-299-A | B28: ='Lipid '!B57 -> 2-8°C_3M | C28: ='Lipid '!C57 -> Glass Vial | D28: ='Lipid '!D57 -> TRF_068-24-088 | E28: ='Lipid '!E57 -> AD/008/24/0700 | F28: Tricaprylin | G28: ='Lipid '!G57 -> 2 | H28: ='Lipid '!O61 -> 100.21936 | I28: =IFERROR((H28*G28/100), "") -> 2.0043871 | J28: =IFERROR((SUM(I28:I31)), "") -> 15.622035 | K28: 100.3 | L28: 13.3 | M28: =IFERROR((K28*L28/100), "") -> 13.3399 | N28: =IFERROR((M28/J28), "") -> 0.85391561
F29: DPPG | G29: ='Lipid '!G58 -> 0.9 | H29: ='Lipid '!O62 -> 84.074192 | I29: =IFERROR((H29*G29/100), "") -> 0.75666773
F30: Cholesterol | G30: ='Lipid '!G59 -> 4.7 | H30: ='Lipid '!O63 -> 101.80779 | I30: =IFERROR((H30*G30/100), "") -> 4.7849659
F31: DEPC | G31: ='Lipid '!G60 -> 8.2 | H31: ='Lipid '!O64 -> 98.487984 | I31: =IFERROR((H31*G31/100), "") -> 8.0760147
A33: ='Lipid '!A66 -> 0 | B33: ='Lipid '!B66 -> 0 | C33: ='Lipid '!C66 -> 0 | D33: ='Lipid '!D66 -> 0 | E33: ='Lipid '!E66 -> 0 | F33: Tricaprylin | G33: ='Lipid '!G66 -> 0 | H33: ='Lipid '!O70 | I33: =IFERROR((H33*G33/100), "") | J33: =IFERROR((SUM(I33:I36)), "") -> 0 | L33: 13.3 | M33: =IFERROR((K33*L33/100), "") -> 0 | N33: =IFERROR((M33/J33), "")
F34: DPPG | G34: ='Lipid '!G67 -> 0 | H34: ='Lipid '!O71 | I34: =IFERROR((H34*G34/100), "")
F35: Cholesterol | G35: ='Lipid '!G68 -> 0 | H35: ='Lipid '!O72 | I35: =IFERROR((H35*G35/100), "")
F36: DEPC | G36: ='Lipid '!G69 -> 0 | H36: ='Lipid '!O73 | I36: =IFERROR((H36*G36/100), "")
A38: ='Lipid '!A75 -> 0 | B38: ='Lipid '!B75 -> 0 | C38: ='Lipid '!C75 -> 0 | D38: ='Lipid '!D75 -> 0 | E38: ='Lipid '!E75 -> 0 | F38: Tricaprylin | G38: ='Lipid '!G75 -> 0 | H38: ='Lipid '!O79 | I38: =IFERROR((H38*G38/100), "") | J38: =IFERROR((SUM(I38:I41)), "") -> 0 | L38: 13.3 | M38: =IFERROR((K38*L38/100), "") -> 0 | N38: =IFERROR((M38/J38), "")
F39: DPPG | G39: ='Lipid '!G76 -> 0 | H39: ='Lipid '!O80 | I39: =IFERROR((H39*G39/100), "")
F40: Cholesterol | G40: ='Lipid '!G77 -> 0 | H40: ='Lipid '!O81 | I40: =IFERROR((H40*G40/100), "")
F41: DEPC | G41: ='Lipid '!G78 -> 0 | H41: ='Lipid '!O82 | I41: =IFERROR((H41*G41/100), "")
A43: ='Lipid '!A84 -> 0 | B43: ='Lipid '!B84 -> 0 | C43: ='Lipid '!C84 -> 0 | D43: ='Lipid '!D84 -> 0 | E43: ='Lipid '!E84 -> 0 | F43: Tricaprylin | G43: ='Lipid '!G84 -> 0 | H43: ='Lipid '!O88 | I43: =IFERROR((H43*G43/100), "") | J43: =IFERROR((SUM(I43:I46)), "") -> 0 | L43: 13.3 | M43: =IFERROR((K43*L43/100), "") -> 0 | N43: =IFERROR((M43/J43), "")
F44: DPPG | G44: ='Lipid '!G85 -> 0 | H44: ='Lipid '!O89 | I44: =IFERROR((H44*G44/100), "")
F45: Cholesterol | G45: ='Lipid '!G86 -> 0 | H45: ='Lipid '!O90 | I45: =IFERROR((H45*G45/100), "")
F46: DEPC | G46: ='Lipid '!G87 -> 0 | H46: ='Lipid '!O91 | I46: =IFERROR((H46*G46/100), "")
A48: ='Lipid '!A93 -> 0 | B48: ='Lipid '!B93 -> 0 | C48: ='Lipid '!C93 -> 0 | D48: ='Lipid '!D93 -> 0 | E48: ='Lipid '!E93 -> 0 | F48: Tricaprylin | G48: ='Lipid '!G93 -> 0 | H48: ='Lipid '!O97 | I48: =IFERROR((H48*G48/100), "") | J48: =IFERROR((SUM(I48:I51)), "") -> 0 | L48: 13.3 | M48: =IFERROR((K48*L48/100), "") -> 0 | N48: =IFERROR((M48/J48), "")
F49: DPPG | G49: ='Lipid '!G94 -> 0 | H49: ='Lipid '!O98 | I49: =IFERROR((H49*G49/100), "")
F50: Cholesterol | G50: ='Lipid '!G95 -> 0 | H50: ='Lipid '!O99 | I50: =IFERROR((H50*G50/100), "")
...
